08:09:14,735 django.utils.autoreload INFO /Users/sunil/Documents/Corteva/project/project/urls.py changed, reloading.
08:13:58,455 django.utils.autoreload INFO /Users/sunil/Documents/Corteva/project/project/urls.py changed, reloading.
08:18:11,597 django.request ERROR Internal Server Error: /docs/
Traceback (most recent call last):
  File "/Users/sunil/miniconda3/envs/django/lib/python3.9/site-packages/django/core/handlers/exception.py", line 55, in inner
    response = get_response(request)
  File "/Users/sunil/miniconda3/envs/django/lib/python3.9/site-packages/django/core/handlers/base.py", line 220, in _get_response
    response = response.render()
  File "/Users/sunil/miniconda3/envs/django/lib/python3.9/site-packages/django/template/response.py", line 111, in render
    self.content = self.rendered_content
  File "/Users/sunil/miniconda3/envs/django/lib/python3.9/site-packages/django/template/response.py", line 87, in rendered_content
    template = self.resolve_template(self.template_name)
  File "/Users/sunil/miniconda3/envs/django/lib/python3.9/site-packages/django/template/response.py", line 69, in resolve_template
    return select_template(template, using=self.using)
  File "/Users/sunil/miniconda3/envs/django/lib/python3.9/site-packages/django/template/loader.py", line 47, in select_template
    raise TemplateDoesNotExist(", ".join(template_name_list), chain=chain)
django.template.exceptions.TemplateDoesNotExist: docs.html
08:21:00,547 django.request WARNING Not Found: /swagger-api
08:22:33,697 django.utils.autoreload INFO /Users/sunil/Documents/Corteva/project/project/settings.py changed, reloading.
08:25:22,263 django.request WARNING Not Found: /docs/index.css
08:25:22,266 django.request WARNING Not Found: /docs/swagger-ui.css
08:25:22,276 django.request WARNING Not Found: /docs/swagger-ui-bundle.js
08:25:22,284 django.request WARNING Not Found: /docs/swagger-ui-standalone-preset.js
08:25:22,285 django.request WARNING Not Found: /docs/swagger-initializer.js
08:25:22,348 django.request WARNING Not Found: /docs/favicon-32x32.png
08:25:22,357 django.request WARNING Not Found: /docs/favicon-16x16.png
08:27:37,447 django.request WARNING Not Found: /docs/openapi.js
08:29:27,652 django.utils.autoreload INFO /Users/sunil/Documents/Corteva/project/project/urls.py changed, reloading.
16:54:35,368 django.utils.autoreload INFO /Users/sunil/Documents/Corteva/project/project/urls.py changed, reloading.
18:11:49,244 django.utils.autoreload INFO /Users/sunil/Documents/Corteva/project/weatherData/views.py changed, reloading.
18:14:02,391 django.utils.autoreload INFO /Users/sunil/Documents/Corteva/project/weatherData/views.py changed, reloading.
18:14:23,358 django.utils.autoreload INFO /Users/sunil/Documents/Corteva/project/weatherData/views.py changed, reloading.
18:14:30,90 django.utils.autoreload INFO /Users/sunil/Documents/Corteva/project/weatherData/views.py changed, reloading.
18:19:24,291 django.utils.autoreload INFO /Users/sunil/Documents/Corteva/project/weatherData/views.py changed, reloading.
18:21:55,975 django.utils.autoreload INFO /Users/sunil/Documents/Corteva/project/weatherData/views.py changed, reloading.
18:28:55,885 django.utils.autoreload INFO /Users/sunil/Documents/Corteva/project/weatherData/views.py changed, reloading.
18:29:12,798 django.utils.autoreload INFO /Users/sunil/Documents/Corteva/project/weatherData/views.py changed, reloading.
18:33:20,955 django.utils.autoreload INFO /Users/sunil/Documents/Corteva/project/weatherData/views.py changed, reloading.
18:33:41,287 django.request ERROR Internal Server Error: /api/weather/stats/
Traceback (most recent call last):
  File "/Users/sunil/miniconda3/envs/django/lib/python3.9/site-packages/django/core/handlers/exception.py", line 55, in inner
    response = get_response(request)
  File "/Users/sunil/miniconda3/envs/django/lib/python3.9/site-packages/django/core/handlers/base.py", line 220, in _get_response
    response = response.render()
  File "/Users/sunil/miniconda3/envs/django/lib/python3.9/site-packages/django/template/response.py", line 111, in render
    self.content = self.rendered_content
  File "/Users/sunil/miniconda3/envs/django/lib/python3.9/site-packages/rest_framework/response.py", line 70, in rendered_content
    ret = renderer.render(self.data, accepted_media_type, context)
  File "/Users/sunil/miniconda3/envs/django/lib/python3.9/site-packages/rest_framework/renderers.py", line 723, in render
    context = self.get_context(data, accepted_media_type, renderer_context)
  File "/Users/sunil/miniconda3/envs/django/lib/python3.9/site-packages/rest_framework/renderers.py", line 654, in get_context
    raw_data_post_form = self.get_raw_data_form(data, view, 'POST', request)
  File "/Users/sunil/miniconda3/envs/django/lib/python3.9/site-packages/rest_framework/renderers.py", line 553, in get_raw_data_form
    serializer = view.get_serializer()
  File "/Users/sunil/miniconda3/envs/django/lib/python3.9/site-packages/rest_framework/generics.py", line 108, in get_serializer
    serializer_class = self.get_serializer_class()
  File "/Users/sunil/miniconda3/envs/django/lib/python3.9/site-packages/rest_framework/generics.py", line 122, in get_serializer_class
    assert self.serializer_class is not None, (
AssertionError: 'WeatherStatsViewSet' should either include a `serializer_class` attribute, or override the `get_serializer_class()` method.
18:36:42,829 django.utils.autoreload INFO /Users/sunil/Documents/Corteva/project/weatherData/views.py changed, reloading.
18:36:48,724 django.request ERROR Internal Server Error: /api/weather/stats/
Traceback (most recent call last):
  File "/Users/sunil/miniconda3/envs/django/lib/python3.9/site-packages/rest_framework/fields.py", line 446, in get_attribute
    return get_attribute(instance, self.source_attrs)
  File "/Users/sunil/miniconda3/envs/django/lib/python3.9/site-packages/rest_framework/fields.py", line 96, in get_attribute
    instance = getattr(instance, attr)
AttributeError: 'WeatherStats' object has no attribute 'date'

During handling of the above exception, another exception occurred:

Traceback (most recent call last):
  File "/Users/sunil/miniconda3/envs/django/lib/python3.9/site-packages/django/core/handlers/exception.py", line 55, in inner
    response = get_response(request)
  File "/Users/sunil/miniconda3/envs/django/lib/python3.9/site-packages/django/core/handlers/base.py", line 197, in _get_response
    response = wrapped_callback(request, *callback_args, **callback_kwargs)
  File "/Users/sunil/miniconda3/envs/django/lib/python3.9/site-packages/django/views/decorators/csrf.py", line 56, in wrapper_view
    return view_func(*args, **kwargs)
  File "/Users/sunil/miniconda3/envs/django/lib/python3.9/site-packages/rest_framework/viewsets.py", line 125, in view
    return self.dispatch(request, *args, **kwargs)
  File "/Users/sunil/miniconda3/envs/django/lib/python3.9/site-packages/rest_framework/views.py", line 509, in dispatch
    response = self.handle_exception(exc)
  File "/Users/sunil/miniconda3/envs/django/lib/python3.9/site-packages/rest_framework/views.py", line 469, in handle_exception
    self.raise_uncaught_exception(exc)
  File "/Users/sunil/miniconda3/envs/django/lib/python3.9/site-packages/rest_framework/views.py", line 480, in raise_uncaught_exception
    raise exc
  File "/Users/sunil/miniconda3/envs/django/lib/python3.9/site-packages/rest_framework/views.py", line 506, in dispatch
    response = handler(request, *args, **kwargs)
  File "/Users/sunil/Documents/Corteva/project/weatherData/views.py", line 67, in list
    return paginator.get_paginated_response(self.serializer_class(page, many=True).data)
  File "/Users/sunil/miniconda3/envs/django/lib/python3.9/site-packages/rest_framework/serializers.py", line 768, in data
    ret = super().data
  File "/Users/sunil/miniconda3/envs/django/lib/python3.9/site-packages/rest_framework/serializers.py", line 253, in data
    self._data = self.to_representation(self.instance)
  File "/Users/sunil/miniconda3/envs/django/lib/python3.9/site-packages/rest_framework/serializers.py", line 686, in to_representation
    return [
  File "/Users/sunil/miniconda3/envs/django/lib/python3.9/site-packages/rest_framework/serializers.py", line 687, in <listcomp>
    self.child.to_representation(item) for item in iterable
  File "/Users/sunil/miniconda3/envs/django/lib/python3.9/site-packages/rest_framework/serializers.py", line 509, in to_representation
    attribute = field.get_attribute(instance)
  File "/Users/sunil/miniconda3/envs/django/lib/python3.9/site-packages/rest_framework/fields.py", line 479, in get_attribute
    raise type(exc)(msg)
AttributeError: Got AttributeError when attempting to get a value for field `date` on serializer `WeatherSerializer`.
The serializer field might be named incorrectly and not match any attribute or key on the `WeatherStats` instance.
Original exception text was: 'WeatherStats' object has no attribute 'date'.
18:38:08,139 django.utils.autoreload INFO /Users/sunil/Documents/Corteva/project/weatherData/views.py changed, reloading.
18:38:13,838 django.request ERROR Internal Server Error: /api/weather/stats/
Traceback (most recent call last):
  File "/Users/sunil/miniconda3/envs/django/lib/python3.9/site-packages/rest_framework/fields.py", line 446, in get_attribute
    return get_attribute(instance, self.source_attrs)
  File "/Users/sunil/miniconda3/envs/django/lib/python3.9/site-packages/rest_framework/fields.py", line 96, in get_attribute
    instance = getattr(instance, attr)
AttributeError: 'WeatherStats' object has no attribute 'date'

During handling of the above exception, another exception occurred:

Traceback (most recent call last):
  File "/Users/sunil/miniconda3/envs/django/lib/python3.9/site-packages/django/core/handlers/exception.py", line 55, in inner
    response = get_response(request)
  File "/Users/sunil/miniconda3/envs/django/lib/python3.9/site-packages/django/core/handlers/base.py", line 197, in _get_response
    response = wrapped_callback(request, *callback_args, **callback_kwargs)
  File "/Users/sunil/miniconda3/envs/django/lib/python3.9/site-packages/django/views/decorators/csrf.py", line 56, in wrapper_view
    return view_func(*args, **kwargs)
  File "/Users/sunil/miniconda3/envs/django/lib/python3.9/site-packages/rest_framework/viewsets.py", line 125, in view
    return self.dispatch(request, *args, **kwargs)
  File "/Users/sunil/miniconda3/envs/django/lib/python3.9/site-packages/rest_framework/views.py", line 509, in dispatch
    response = self.handle_exception(exc)
  File "/Users/sunil/miniconda3/envs/django/lib/python3.9/site-packages/rest_framework/views.py", line 469, in handle_exception
    self.raise_uncaught_exception(exc)
  File "/Users/sunil/miniconda3/envs/django/lib/python3.9/site-packages/rest_framework/views.py", line 480, in raise_uncaught_exception
    raise exc
  File "/Users/sunil/miniconda3/envs/django/lib/python3.9/site-packages/rest_framework/views.py", line 506, in dispatch
    response = handler(request, *args, **kwargs)
  File "/Users/sunil/Documents/Corteva/project/weatherData/views.py", line 67, in list
    return paginator.get_paginated_response(self.serializer_class(page, many=True).data)
  File "/Users/sunil/miniconda3/envs/django/lib/python3.9/site-packages/rest_framework/serializers.py", line 768, in data
    ret = super().data
  File "/Users/sunil/miniconda3/envs/django/lib/python3.9/site-packages/rest_framework/serializers.py", line 253, in data
    self._data = self.to_representation(self.instance)
  File "/Users/sunil/miniconda3/envs/django/lib/python3.9/site-packages/rest_framework/serializers.py", line 686, in to_representation
    return [
  File "/Users/sunil/miniconda3/envs/django/lib/python3.9/site-packages/rest_framework/serializers.py", line 687, in <listcomp>
    self.child.to_representation(item) for item in iterable
  File "/Users/sunil/miniconda3/envs/django/lib/python3.9/site-packages/rest_framework/serializers.py", line 509, in to_representation
    attribute = field.get_attribute(instance)
  File "/Users/sunil/miniconda3/envs/django/lib/python3.9/site-packages/rest_framework/fields.py", line 479, in get_attribute
    raise type(exc)(msg)
AttributeError: Got AttributeError when attempting to get a value for field `date` on serializer `WeatherSerializer`.
The serializer field might be named incorrectly and not match any attribute or key on the `WeatherStats` instance.
Original exception text was: 'WeatherStats' object has no attribute 'date'.
18:38:55,139 django.utils.autoreload INFO /Users/sunil/Documents/Corteva/project/weatherData/views.py changed, reloading.
18:38:58,482 django.request ERROR Internal Server Error: /api/weather/stats/
Traceback (most recent call last):
  File "/Users/sunil/miniconda3/envs/django/lib/python3.9/site-packages/rest_framework/fields.py", line 446, in get_attribute
    return get_attribute(instance, self.source_attrs)
  File "/Users/sunil/miniconda3/envs/django/lib/python3.9/site-packages/rest_framework/fields.py", line 96, in get_attribute
    instance = getattr(instance, attr)
AttributeError: 'WeatherStats' object has no attribute 'date'

During handling of the above exception, another exception occurred:

Traceback (most recent call last):
  File "/Users/sunil/miniconda3/envs/django/lib/python3.9/site-packages/django/core/handlers/exception.py", line 55, in inner
    response = get_response(request)
  File "/Users/sunil/miniconda3/envs/django/lib/python3.9/site-packages/django/core/handlers/base.py", line 197, in _get_response
    response = wrapped_callback(request, *callback_args, **callback_kwargs)
  File "/Users/sunil/miniconda3/envs/django/lib/python3.9/site-packages/django/views/decorators/csrf.py", line 56, in wrapper_view
    return view_func(*args, **kwargs)
  File "/Users/sunil/miniconda3/envs/django/lib/python3.9/site-packages/rest_framework/viewsets.py", line 125, in view
    return self.dispatch(request, *args, **kwargs)
  File "/Users/sunil/miniconda3/envs/django/lib/python3.9/site-packages/rest_framework/views.py", line 509, in dispatch
    response = self.handle_exception(exc)
  File "/Users/sunil/miniconda3/envs/django/lib/python3.9/site-packages/rest_framework/views.py", line 469, in handle_exception
    self.raise_uncaught_exception(exc)
  File "/Users/sunil/miniconda3/envs/django/lib/python3.9/site-packages/rest_framework/views.py", line 480, in raise_uncaught_exception
    raise exc
  File "/Users/sunil/miniconda3/envs/django/lib/python3.9/site-packages/rest_framework/views.py", line 506, in dispatch
    response = handler(request, *args, **kwargs)
  File "/Users/sunil/Documents/Corteva/project/weatherData/views.py", line 67, in list
    return paginator.get_paginated_response(self.serializer_class(page, many=True).data)
  File "/Users/sunil/miniconda3/envs/django/lib/python3.9/site-packages/rest_framework/serializers.py", line 768, in data
    ret = super().data
  File "/Users/sunil/miniconda3/envs/django/lib/python3.9/site-packages/rest_framework/serializers.py", line 253, in data
    self._data = self.to_representation(self.instance)
  File "/Users/sunil/miniconda3/envs/django/lib/python3.9/site-packages/rest_framework/serializers.py", line 686, in to_representation
    return [
  File "/Users/sunil/miniconda3/envs/django/lib/python3.9/site-packages/rest_framework/serializers.py", line 687, in <listcomp>
    self.child.to_representation(item) for item in iterable
  File "/Users/sunil/miniconda3/envs/django/lib/python3.9/site-packages/rest_framework/serializers.py", line 509, in to_representation
    attribute = field.get_attribute(instance)
  File "/Users/sunil/miniconda3/envs/django/lib/python3.9/site-packages/rest_framework/fields.py", line 479, in get_attribute
    raise type(exc)(msg)
AttributeError: Got AttributeError when attempting to get a value for field `date` on serializer `WeatherSerializer`.
The serializer field might be named incorrectly and not match any attribute or key on the `WeatherStats` instance.
Original exception text was: 'WeatherStats' object has no attribute 'date'.
18:41:26,626 django.utils.autoreload INFO /Users/sunil/Documents/Corteva/project/weatherData/views.py changed, reloading.
18:41:30,372 django.request ERROR Internal Server Error: /api/weather/stats/
Traceback (most recent call last):
  File "/Users/sunil/miniconda3/envs/django/lib/python3.9/site-packages/rest_framework/fields.py", line 446, in get_attribute
    return get_attribute(instance, self.source_attrs)
  File "/Users/sunil/miniconda3/envs/django/lib/python3.9/site-packages/rest_framework/fields.py", line 96, in get_attribute
    instance = getattr(instance, attr)
AttributeError: 'WeatherStats' object has no attribute 'date'

During handling of the above exception, another exception occurred:

Traceback (most recent call last):
  File "/Users/sunil/miniconda3/envs/django/lib/python3.9/site-packages/django/core/handlers/exception.py", line 55, in inner
    response = get_response(request)
  File "/Users/sunil/miniconda3/envs/django/lib/python3.9/site-packages/django/core/handlers/base.py", line 197, in _get_response
    response = wrapped_callback(request, *callback_args, **callback_kwargs)
  File "/Users/sunil/miniconda3/envs/django/lib/python3.9/site-packages/django/views/decorators/csrf.py", line 56, in wrapper_view
    return view_func(*args, **kwargs)
  File "/Users/sunil/miniconda3/envs/django/lib/python3.9/site-packages/rest_framework/viewsets.py", line 125, in view
    return self.dispatch(request, *args, **kwargs)
  File "/Users/sunil/miniconda3/envs/django/lib/python3.9/site-packages/rest_framework/views.py", line 509, in dispatch
    response = self.handle_exception(exc)
  File "/Users/sunil/miniconda3/envs/django/lib/python3.9/site-packages/rest_framework/views.py", line 469, in handle_exception
    self.raise_uncaught_exception(exc)
  File "/Users/sunil/miniconda3/envs/django/lib/python3.9/site-packages/rest_framework/views.py", line 480, in raise_uncaught_exception
    raise exc
  File "/Users/sunil/miniconda3/envs/django/lib/python3.9/site-packages/rest_framework/views.py", line 506, in dispatch
    response = handler(request, *args, **kwargs)
  File "/Users/sunil/Documents/Corteva/project/weatherData/views.py", line 68, in list
    return paginator.get_paginated_response(serializer.data)
  File "/Users/sunil/miniconda3/envs/django/lib/python3.9/site-packages/rest_framework/serializers.py", line 768, in data
    ret = super().data
  File "/Users/sunil/miniconda3/envs/django/lib/python3.9/site-packages/rest_framework/serializers.py", line 253, in data
    self._data = self.to_representation(self.instance)
  File "/Users/sunil/miniconda3/envs/django/lib/python3.9/site-packages/rest_framework/serializers.py", line 686, in to_representation
    return [
  File "/Users/sunil/miniconda3/envs/django/lib/python3.9/site-packages/rest_framework/serializers.py", line 687, in <listcomp>
    self.child.to_representation(item) for item in iterable
  File "/Users/sunil/miniconda3/envs/django/lib/python3.9/site-packages/rest_framework/serializers.py", line 509, in to_representation
    attribute = field.get_attribute(instance)
  File "/Users/sunil/miniconda3/envs/django/lib/python3.9/site-packages/rest_framework/fields.py", line 479, in get_attribute
    raise type(exc)(msg)
AttributeError: Got AttributeError when attempting to get a value for field `date` on serializer `WeatherSerializer`.
The serializer field might be named incorrectly and not match any attribute or key on the `WeatherStats` instance.
Original exception text was: 'WeatherStats' object has no attribute 'date'.
18:41:52,673 django.utils.autoreload INFO /Users/sunil/Documents/Corteva/project/weatherData/views.py changed, reloading.
18:42:08,623 django.utils.autoreload INFO /Users/sunil/Documents/Corteva/project/weatherData/views.py changed, reloading.
18:44:13,904 django.utils.autoreload INFO /Users/sunil/Documents/Corteva/project/weatherData/views.py changed, reloading.
18:44:27,675 django.utils.autoreload INFO /Users/sunil/Documents/Corteva/project/weatherData/views.py changed, reloading.
18:54:10,188 django.utils.autoreload INFO /Users/sunil/Documents/Corteva/project/weatherData/views.py changed, reloading.
18:54:24,685 django.request ERROR Internal Server Error: /api/weather/stats/
Traceback (most recent call last):
  File "/Users/sunil/miniconda3/envs/django/lib/python3.9/site-packages/django/core/handlers/exception.py", line 55, in inner
    response = get_response(request)
  File "/Users/sunil/miniconda3/envs/django/lib/python3.9/site-packages/django/core/handlers/base.py", line 197, in _get_response
    response = wrapped_callback(request, *callback_args, **callback_kwargs)
  File "/Users/sunil/miniconda3/envs/django/lib/python3.9/site-packages/django/views/decorators/csrf.py", line 56, in wrapper_view
    return view_func(*args, **kwargs)
  File "/Users/sunil/miniconda3/envs/django/lib/python3.9/site-packages/rest_framework/viewsets.py", line 125, in view
    return self.dispatch(request, *args, **kwargs)
  File "/Users/sunil/miniconda3/envs/django/lib/python3.9/site-packages/rest_framework/views.py", line 509, in dispatch
    response = self.handle_exception(exc)
  File "/Users/sunil/miniconda3/envs/django/lib/python3.9/site-packages/rest_framework/views.py", line 469, in handle_exception
    self.raise_uncaught_exception(exc)
  File "/Users/sunil/miniconda3/envs/django/lib/python3.9/site-packages/rest_framework/views.py", line 480, in raise_uncaught_exception
    raise exc
  File "/Users/sunil/miniconda3/envs/django/lib/python3.9/site-packages/rest_framework/views.py", line 506, in dispatch
    response = handler(request, *args, **kwargs)
  File "/Users/sunil/miniconda3/envs/django/lib/python3.9/site-packages/rest_framework/mixins.py", line 54, in retrieve
    instance = self.get_object()
  File "/Users/sunil/miniconda3/envs/django/lib/python3.9/site-packages/rest_framework/generics.py", line 83, in get_object
    queryset = self.filter_queryset(self.get_queryset())
  File "/Users/sunil/miniconda3/envs/django/lib/python3.9/site-packages/rest_framework/generics.py", line 63, in get_queryset
    assert self.queryset is not None, (
AssertionError: 'WeatherViewSet' should either include a `queryset` attribute, or override the `get_queryset()` method.
18:54:52,387 django.request ERROR Internal Server Error: /api/weather/stats/
Traceback (most recent call last):
  File "/Users/sunil/miniconda3/envs/django/lib/python3.9/site-packages/django/core/handlers/exception.py", line 55, in inner
    response = get_response(request)
  File "/Users/sunil/miniconda3/envs/django/lib/python3.9/site-packages/django/core/handlers/base.py", line 197, in _get_response
    response = wrapped_callback(request, *callback_args, **callback_kwargs)
  File "/Users/sunil/miniconda3/envs/django/lib/python3.9/site-packages/django/views/decorators/csrf.py", line 56, in wrapper_view
    return view_func(*args, **kwargs)
  File "/Users/sunil/miniconda3/envs/django/lib/python3.9/site-packages/rest_framework/viewsets.py", line 125, in view
    return self.dispatch(request, *args, **kwargs)
  File "/Users/sunil/miniconda3/envs/django/lib/python3.9/site-packages/rest_framework/views.py", line 509, in dispatch
    response = self.handle_exception(exc)
  File "/Users/sunil/miniconda3/envs/django/lib/python3.9/site-packages/rest_framework/views.py", line 469, in handle_exception
    self.raise_uncaught_exception(exc)
  File "/Users/sunil/miniconda3/envs/django/lib/python3.9/site-packages/rest_framework/views.py", line 480, in raise_uncaught_exception
    raise exc
  File "/Users/sunil/miniconda3/envs/django/lib/python3.9/site-packages/rest_framework/views.py", line 506, in dispatch
    response = handler(request, *args, **kwargs)
  File "/Users/sunil/miniconda3/envs/django/lib/python3.9/site-packages/rest_framework/mixins.py", line 54, in retrieve
    instance = self.get_object()
  File "/Users/sunil/miniconda3/envs/django/lib/python3.9/site-packages/rest_framework/generics.py", line 83, in get_object
    queryset = self.filter_queryset(self.get_queryset())
  File "/Users/sunil/miniconda3/envs/django/lib/python3.9/site-packages/rest_framework/generics.py", line 63, in get_queryset
    assert self.queryset is not None, (
AssertionError: 'WeatherViewSet' should either include a `queryset` attribute, or override the `get_queryset()` method.
18:55:48,569 django.utils.autoreload INFO /Users/sunil/Documents/Corteva/project/weatherData/views.py changed, reloading.
18:55:51,107 django.utils.autoreload INFO /Users/sunil/Documents/Corteva/project/weatherData/views.py changed, reloading.
18:55:55,361 django.request WARNING Not Found: /api/weather/stats/
18:56:26,532 django.utils.autoreload INFO /Users/sunil/Documents/Corteva/project/weatherData/views.py changed, reloading.
18:56:30,514 django.request WARNING Not Found: /api/weather/stats/
18:57:01,119 django.utils.autoreload INFO /Users/sunil/Documents/Corteva/project/weatherData/views.py changed, reloading.
18:57:09,736 django.request WARNING Not Found: /api/weather/stats/
18:57:13,544 django.request WARNING Not Found: /api/weather/stats/
18:57:21,229 django.utils.autoreload INFO /Users/sunil/Documents/Corteva/project/weatherData/views.py changed, reloading.
18:57:23,937 django.request WARNING Not Found: /api/weather/stats/
18:57:33,245 django.utils.autoreload INFO /Users/sunil/Documents/Corteva/project/weatherData/views.py changed, reloading.
18:57:35,893 django.request ERROR Internal Server Error: /api/weather/stats/
Traceback (most recent call last):
  File "/Users/sunil/miniconda3/envs/django/lib/python3.9/site-packages/django/core/handlers/exception.py", line 55, in inner
    response = get_response(request)
  File "/Users/sunil/miniconda3/envs/django/lib/python3.9/site-packages/django/core/handlers/base.py", line 197, in _get_response
    response = wrapped_callback(request, *callback_args, **callback_kwargs)
  File "/Users/sunil/miniconda3/envs/django/lib/python3.9/site-packages/django/views/decorators/csrf.py", line 56, in wrapper_view
    return view_func(*args, **kwargs)
  File "/Users/sunil/miniconda3/envs/django/lib/python3.9/site-packages/rest_framework/viewsets.py", line 125, in view
    return self.dispatch(request, *args, **kwargs)
  File "/Users/sunil/miniconda3/envs/django/lib/python3.9/site-packages/rest_framework/views.py", line 509, in dispatch
    response = self.handle_exception(exc)
  File "/Users/sunil/miniconda3/envs/django/lib/python3.9/site-packages/rest_framework/views.py", line 469, in handle_exception
    self.raise_uncaught_exception(exc)
  File "/Users/sunil/miniconda3/envs/django/lib/python3.9/site-packages/rest_framework/views.py", line 480, in raise_uncaught_exception
    raise exc
  File "/Users/sunil/miniconda3/envs/django/lib/python3.9/site-packages/rest_framework/views.py", line 506, in dispatch
    response = handler(request, *args, **kwargs)
  File "/Users/sunil/miniconda3/envs/django/lib/python3.9/site-packages/rest_framework/mixins.py", line 54, in retrieve
    instance = self.get_object()
  File "/Users/sunil/miniconda3/envs/django/lib/python3.9/site-packages/rest_framework/generics.py", line 83, in get_object
    queryset = self.filter_queryset(self.get_queryset())
  File "/Users/sunil/miniconda3/envs/django/lib/python3.9/site-packages/rest_framework/generics.py", line 63, in get_queryset
    assert self.queryset is not None, (
AssertionError: 'WeatherViewSet' should either include a `queryset` attribute, or override the `get_queryset()` method.
18:57:50,207 django.utils.autoreload INFO /Users/sunil/Documents/Corteva/project/weatherData/views.py changed, reloading.
18:57:51,819 django.request ERROR Internal Server Error: /api/weather/stats/
Traceback (most recent call last):
  File "/Users/sunil/miniconda3/envs/django/lib/python3.9/site-packages/django/core/handlers/exception.py", line 55, in inner
    response = get_response(request)
  File "/Users/sunil/miniconda3/envs/django/lib/python3.9/site-packages/django/core/handlers/base.py", line 197, in _get_response
    response = wrapped_callback(request, *callback_args, **callback_kwargs)
  File "/Users/sunil/miniconda3/envs/django/lib/python3.9/site-packages/django/views/decorators/csrf.py", line 56, in wrapper_view
    return view_func(*args, **kwargs)
  File "/Users/sunil/miniconda3/envs/django/lib/python3.9/site-packages/rest_framework/viewsets.py", line 125, in view
    return self.dispatch(request, *args, **kwargs)
  File "/Users/sunil/miniconda3/envs/django/lib/python3.9/site-packages/rest_framework/views.py", line 509, in dispatch
    response = self.handle_exception(exc)
  File "/Users/sunil/miniconda3/envs/django/lib/python3.9/site-packages/rest_framework/views.py", line 469, in handle_exception
    self.raise_uncaught_exception(exc)
  File "/Users/sunil/miniconda3/envs/django/lib/python3.9/site-packages/rest_framework/views.py", line 480, in raise_uncaught_exception
    raise exc
  File "/Users/sunil/miniconda3/envs/django/lib/python3.9/site-packages/rest_framework/views.py", line 506, in dispatch
    response = handler(request, *args, **kwargs)
  File "/Users/sunil/miniconda3/envs/django/lib/python3.9/site-packages/rest_framework/mixins.py", line 54, in retrieve
    instance = self.get_object()
  File "/Users/sunil/miniconda3/envs/django/lib/python3.9/site-packages/rest_framework/generics.py", line 83, in get_object
    queryset = self.filter_queryset(self.get_queryset())
  File "/Users/sunil/miniconda3/envs/django/lib/python3.9/site-packages/rest_framework/generics.py", line 63, in get_queryset
    assert self.queryset is not None, (
AssertionError: 'WeatherViewSet' should either include a `queryset` attribute, or override the `get_queryset()` method.
18:58:12,308 django.utils.autoreload INFO /Users/sunil/Documents/Corteva/project/weatherData/views.py changed, reloading.
18:58:16,398 django.request ERROR Internal Server Error: /api/weather/stats/
Traceback (most recent call last):
  File "/Users/sunil/miniconda3/envs/django/lib/python3.9/site-packages/django/core/handlers/exception.py", line 55, in inner
    response = get_response(request)
  File "/Users/sunil/miniconda3/envs/django/lib/python3.9/site-packages/django/core/handlers/base.py", line 197, in _get_response
    response = wrapped_callback(request, *callback_args, **callback_kwargs)
  File "/Users/sunil/miniconda3/envs/django/lib/python3.9/site-packages/django/views/decorators/csrf.py", line 56, in wrapper_view
    return view_func(*args, **kwargs)
  File "/Users/sunil/miniconda3/envs/django/lib/python3.9/site-packages/rest_framework/viewsets.py", line 125, in view
    return self.dispatch(request, *args, **kwargs)
  File "/Users/sunil/miniconda3/envs/django/lib/python3.9/site-packages/rest_framework/views.py", line 509, in dispatch
    response = self.handle_exception(exc)
  File "/Users/sunil/miniconda3/envs/django/lib/python3.9/site-packages/rest_framework/views.py", line 469, in handle_exception
    self.raise_uncaught_exception(exc)
  File "/Users/sunil/miniconda3/envs/django/lib/python3.9/site-packages/rest_framework/views.py", line 480, in raise_uncaught_exception
    raise exc
  File "/Users/sunil/miniconda3/envs/django/lib/python3.9/site-packages/rest_framework/views.py", line 506, in dispatch
    response = handler(request, *args, **kwargs)
  File "/Users/sunil/miniconda3/envs/django/lib/python3.9/site-packages/rest_framework/mixins.py", line 54, in retrieve
    instance = self.get_object()
  File "/Users/sunil/miniconda3/envs/django/lib/python3.9/site-packages/rest_framework/generics.py", line 83, in get_object
    queryset = self.filter_queryset(self.get_queryset())
  File "/Users/sunil/miniconda3/envs/django/lib/python3.9/site-packages/rest_framework/generics.py", line 63, in get_queryset
    assert self.queryset is not None, (
AssertionError: 'WeatherViewSet' should either include a `queryset` attribute, or override the `get_queryset()` method.
18:59:37,793 django.utils.autoreload INFO /Users/sunil/Documents/Corteva/project/weatherData/views.py changed, reloading.
19:00:19,110 django.utils.autoreload INFO /Users/sunil/Documents/Corteva/project/weatherData/views.py changed, reloading.
19:00:24,710 django.utils.autoreload INFO /Users/sunil/Documents/Corteva/project/weatherData/views.py changed, reloading.
19:00:30,377 django.request ERROR Internal Server Error: /api/weather/stats/
Traceback (most recent call last):
  File "/Users/sunil/miniconda3/envs/django/lib/python3.9/site-packages/django/core/handlers/exception.py", line 55, in inner
    response = get_response(request)
  File "/Users/sunil/miniconda3/envs/django/lib/python3.9/site-packages/django/core/handlers/base.py", line 197, in _get_response
    response = wrapped_callback(request, *callback_args, **callback_kwargs)
  File "/Users/sunil/miniconda3/envs/django/lib/python3.9/site-packages/django/views/decorators/csrf.py", line 56, in wrapper_view
    return view_func(*args, **kwargs)
  File "/Users/sunil/miniconda3/envs/django/lib/python3.9/site-packages/rest_framework/viewsets.py", line 125, in view
    return self.dispatch(request, *args, **kwargs)
  File "/Users/sunil/miniconda3/envs/django/lib/python3.9/site-packages/rest_framework/views.py", line 509, in dispatch
    response = self.handle_exception(exc)
  File "/Users/sunil/miniconda3/envs/django/lib/python3.9/site-packages/rest_framework/views.py", line 469, in handle_exception
    self.raise_uncaught_exception(exc)
  File "/Users/sunil/miniconda3/envs/django/lib/python3.9/site-packages/rest_framework/views.py", line 480, in raise_uncaught_exception
    raise exc
  File "/Users/sunil/miniconda3/envs/django/lib/python3.9/site-packages/rest_framework/views.py", line 506, in dispatch
    response = handler(request, *args, **kwargs)
  File "/Users/sunil/miniconda3/envs/django/lib/python3.9/site-packages/rest_framework/mixins.py", line 54, in retrieve
    instance = self.get_object()
  File "/Users/sunil/miniconda3/envs/django/lib/python3.9/site-packages/rest_framework/generics.py", line 83, in get_object
    queryset = self.filter_queryset(self.get_queryset())
  File "/Users/sunil/miniconda3/envs/django/lib/python3.9/site-packages/rest_framework/generics.py", line 63, in get_queryset
    assert self.queryset is not None, (
AssertionError: 'WeatherViewSet' should either include a `queryset` attribute, or override the `get_queryset()` method.
19:00:31,207 django.request ERROR Internal Server Error: /api/weather/stats/
Traceback (most recent call last):
  File "/Users/sunil/miniconda3/envs/django/lib/python3.9/site-packages/django/core/handlers/exception.py", line 55, in inner
    response = get_response(request)
  File "/Users/sunil/miniconda3/envs/django/lib/python3.9/site-packages/django/core/handlers/base.py", line 197, in _get_response
    response = wrapped_callback(request, *callback_args, **callback_kwargs)
  File "/Users/sunil/miniconda3/envs/django/lib/python3.9/site-packages/django/views/decorators/csrf.py", line 56, in wrapper_view
    return view_func(*args, **kwargs)
  File "/Users/sunil/miniconda3/envs/django/lib/python3.9/site-packages/rest_framework/viewsets.py", line 125, in view
    return self.dispatch(request, *args, **kwargs)
  File "/Users/sunil/miniconda3/envs/django/lib/python3.9/site-packages/rest_framework/views.py", line 509, in dispatch
    response = self.handle_exception(exc)
  File "/Users/sunil/miniconda3/envs/django/lib/python3.9/site-packages/rest_framework/views.py", line 469, in handle_exception
    self.raise_uncaught_exception(exc)
  File "/Users/sunil/miniconda3/envs/django/lib/python3.9/site-packages/rest_framework/views.py", line 480, in raise_uncaught_exception
    raise exc
  File "/Users/sunil/miniconda3/envs/django/lib/python3.9/site-packages/rest_framework/views.py", line 506, in dispatch
    response = handler(request, *args, **kwargs)
  File "/Users/sunil/miniconda3/envs/django/lib/python3.9/site-packages/rest_framework/mixins.py", line 54, in retrieve
    instance = self.get_object()
  File "/Users/sunil/miniconda3/envs/django/lib/python3.9/site-packages/rest_framework/generics.py", line 83, in get_object
    queryset = self.filter_queryset(self.get_queryset())
  File "/Users/sunil/miniconda3/envs/django/lib/python3.9/site-packages/rest_framework/generics.py", line 63, in get_queryset
    assert self.queryset is not None, (
AssertionError: 'WeatherViewSet' should either include a `queryset` attribute, or override the `get_queryset()` method.
19:01:00,714 django.request ERROR Internal Server Error: /api/weather/stats/
Traceback (most recent call last):
  File "/Users/sunil/miniconda3/envs/django/lib/python3.9/site-packages/django/core/handlers/exception.py", line 55, in inner
    response = get_response(request)
  File "/Users/sunil/miniconda3/envs/django/lib/python3.9/site-packages/django/core/handlers/base.py", line 197, in _get_response
    response = wrapped_callback(request, *callback_args, **callback_kwargs)
  File "/Users/sunil/miniconda3/envs/django/lib/python3.9/site-packages/django/views/decorators/csrf.py", line 56, in wrapper_view
    return view_func(*args, **kwargs)
  File "/Users/sunil/miniconda3/envs/django/lib/python3.9/site-packages/rest_framework/viewsets.py", line 125, in view
    return self.dispatch(request, *args, **kwargs)
  File "/Users/sunil/miniconda3/envs/django/lib/python3.9/site-packages/rest_framework/views.py", line 509, in dispatch
    response = self.handle_exception(exc)
  File "/Users/sunil/miniconda3/envs/django/lib/python3.9/site-packages/rest_framework/views.py", line 469, in handle_exception
    self.raise_uncaught_exception(exc)
  File "/Users/sunil/miniconda3/envs/django/lib/python3.9/site-packages/rest_framework/views.py", line 480, in raise_uncaught_exception
    raise exc
  File "/Users/sunil/miniconda3/envs/django/lib/python3.9/site-packages/rest_framework/views.py", line 506, in dispatch
    response = handler(request, *args, **kwargs)
  File "/Users/sunil/miniconda3/envs/django/lib/python3.9/site-packages/rest_framework/mixins.py", line 54, in retrieve
    instance = self.get_object()
  File "/Users/sunil/miniconda3/envs/django/lib/python3.9/site-packages/rest_framework/generics.py", line 83, in get_object
    queryset = self.filter_queryset(self.get_queryset())
  File "/Users/sunil/miniconda3/envs/django/lib/python3.9/site-packages/rest_framework/generics.py", line 63, in get_queryset
    assert self.queryset is not None, (
AssertionError: 'WeatherViewSet' should either include a `queryset` attribute, or override the `get_queryset()` method.
19:01:25,958 django.utils.autoreload INFO /Users/sunil/Documents/Corteva/project/weatherData/views.py changed, reloading.
19:01:28,966 django.request WARNING Not Found: /api/weather/stats/
19:03:23,399 django.request WARNING Not Found: /api/weather/stats/
19:03:40,572 django.utils.autoreload INFO /Users/sunil/Documents/Corteva/project/weatherData/views.py changed, reloading.
19:03:43,642 django.request WARNING Not Found: /api/weather/stats/
19:03:44,339 django.request WARNING Not Found: /api/weather/stats/
19:03:50,510 django.request WARNING Not Found: /api/weather/stats/
19:04:43,463 django.utils.autoreload INFO /Users/sunil/Documents/Corteva/project/weatherData/views.py changed, reloading.
19:04:47,132 django.request WARNING Not Found: /api/weather/stats/
19:04:48,108 django.request WARNING Not Found: /api/weather/stats/
19:05:31,139 django.request WARNING Not Found: /api/weather/stats/
19:06:18,371 django.utils.autoreload INFO /Users/sunil/Documents/Corteva/project/weatherData/views.py changed, reloading.
19:07:01,807 django.utils.autoreload INFO /Users/sunil/Documents/Corteva/project/weatherData/views.py changed, reloading.
19:07:09,228 django.request WARNING Not Found: /api/weather/stats/
19:13:44,619 django.utils.autoreload INFO /Users/sunil/Documents/Corteva/project/weatherData/views.py changed, reloading.
19:14:52,627 django.request WARNING Not Found: /api/weather/stats/
19:17:25,867 django.utils.autoreload INFO /Users/sunil/Documents/Corteva/project/weatherData/views.py changed, reloading.
19:18:07,939 django.request WARNING Not Found: /api/weather/stats/
19:18:23,126 django.utils.autoreload INFO /Users/sunil/Documents/Corteva/project/weatherData/views.py changed, reloading.
19:18:52,255 django.utils.autoreload INFO /Users/sunil/Documents/Corteva/project/weatherData/views.py changed, reloading.
19:26:18,517 django.utils.autoreload INFO /Users/sunil/Documents/Corteva/project/weatherData/views.py changed, reloading.
19:35:32,850 django.utils.autoreload INFO /Users/sunil/Documents/Corteva/project/weatherData/urls.py changed, reloading.
19:43:04,565 django.utils.autoreload INFO /Users/sunil/Documents/Corteva/project/weatherData/urls.py changed, reloading.
19:43:51,318 django.utils.autoreload INFO /Users/sunil/Documents/Corteva/project/weatherData/urls.py changed, reloading.
19:44:16,139 django.request WARNING Not Found: /weather
19:44:34,820 django.request WARNING Not Found: /api/weather/stats/
19:55:17,426 django.utils.autoreload INFO /Users/sunil/Documents/Corteva/project/weatherData/urls.py changed, reloading.
19:55:22,204 django.request WARNING Not Found: /api/weather/stats/
19:55:37,703 django.utils.autoreload INFO /Users/sunil/Documents/Corteva/project/weatherData/urls.py changed, reloading.
19:56:34,176 django.utils.autoreload INFO /Users/sunil/Documents/Corteva/project/weatherData/views.py changed, reloading.
19:57:03,255 django.utils.autoreload INFO /Users/sunil/Documents/Corteva/project/weatherData/views.py changed, reloading.
19:57:07,70 django.request WARNING Not Found: /api/weather/stats//
19:57:08,31 django.request WARNING Not Found: /api/weather/stats//
19:57:24,735 django.request WARNING Not Found: /api/weather/stats/fr
19:58:06,191 django.request WARNING Not Found: /api/weather/stats/filter/station_id=sds
19:58:20,91 django.request WARNING Not Found: /api/weather/stats/filter/
19:58:47,251 django.utils.autoreload INFO /Users/sunil/Documents/Corteva/project/weatherData/views.py changed, reloading.
19:58:56,505 django.request WARNING Not Found: /api/weather/stats/filter/
19:59:28,564 django.request WARNING Not Found: /api/weather/stats/filter/station_id=sdsd
19:59:44,469 django.request WARNING Not Found: /api/weather/stats/filter/
20:02:09,141 django.request WARNING Not Found: /api/weather/stats/filter/station_id=sdsd
20:03:15,707 django.utils.autoreload INFO /Users/sunil/Documents/Corteva/project/weatherData/views.py changed, reloading.
20:03:19,150 django.request WARNING Not Found: /api/weather/stats/filter/station_id=sdsd
20:03:39,821 django.request WARNING Not Found: /api/weather/stats/filter/station_id=USC00110072
20:05:08,226 django.utils.autoreload INFO /Users/sunil/Documents/Corteva/project/weatherData/views.py changed, reloading.
20:05:24,89 django.utils.autoreload INFO /Users/sunil/Documents/Corteva/project/weatherData/views.py changed, reloading.
20:06:45,899 django.utils.autoreload INFO /Users/sunil/Documents/Corteva/project/weatherData/views.py changed, reloading.
20:09:07,375 django.utils.autoreload INFO /Users/sunil/Documents/Corteva/project/weatherData/views.py changed, reloading.
20:09:29,248 django.utils.autoreload INFO /Users/sunil/Documents/Corteva/project/weatherData/views.py changed, reloading.
20:09:39,943 django.utils.autoreload INFO /Users/sunil/Documents/Corteva/project/weatherData/views.py changed, reloading.
20:10:21,204 django.utils.autoreload INFO /Users/sunil/Documents/Corteva/project/weatherData/views.py changed, reloading.
20:10:28,901 django.utils.autoreload INFO /Users/sunil/Documents/Corteva/project/weatherData/views.py changed, reloading.
20:11:23,968 django.request ERROR Internal Server Error: /api/weather/filter/date=19850101/
Traceback (most recent call last):
  File "/Users/sunil/miniconda3/envs/django/lib/python3.9/site-packages/django/core/handlers/exception.py", line 55, in inner
    response = get_response(request)
  File "/Users/sunil/miniconda3/envs/django/lib/python3.9/site-packages/django/core/handlers/base.py", line 197, in _get_response
    response = wrapped_callback(request, *callback_args, **callback_kwargs)
  File "/Users/sunil/miniconda3/envs/django/lib/python3.9/site-packages/django/views/decorators/csrf.py", line 56, in wrapper_view
    return view_func(*args, **kwargs)
  File "/Users/sunil/miniconda3/envs/django/lib/python3.9/site-packages/rest_framework/viewsets.py", line 125, in view
    return self.dispatch(request, *args, **kwargs)
  File "/Users/sunil/miniconda3/envs/django/lib/python3.9/site-packages/rest_framework/views.py", line 509, in dispatch
    response = self.handle_exception(exc)
  File "/Users/sunil/miniconda3/envs/django/lib/python3.9/site-packages/rest_framework/views.py", line 469, in handle_exception
    self.raise_uncaught_exception(exc)
  File "/Users/sunil/miniconda3/envs/django/lib/python3.9/site-packages/rest_framework/views.py", line 480, in raise_uncaught_exception
    raise exc
  File "/Users/sunil/miniconda3/envs/django/lib/python3.9/site-packages/rest_framework/views.py", line 506, in dispatch
    response = handler(request, *args, **kwargs)
  File "/Users/sunil/Documents/Corteva/project/weatherData/views.py", line 65, in retrive_date
    queryset = Weather.objects.filter(date=date)
  File "/Users/sunil/miniconda3/envs/django/lib/python3.9/site-packages/django/db/models/manager.py", line 87, in manager_method
    return getattr(self.get_queryset(), name)(*args, **kwargs)
  File "/Users/sunil/miniconda3/envs/django/lib/python3.9/site-packages/django/db/models/query.py", line 1436, in filter
    return self._filter_or_exclude(False, args, kwargs)
  File "/Users/sunil/miniconda3/envs/django/lib/python3.9/site-packages/django/db/models/query.py", line 1454, in _filter_or_exclude
    clone._filter_or_exclude_inplace(negate, args, kwargs)
  File "/Users/sunil/miniconda3/envs/django/lib/python3.9/site-packages/django/db/models/query.py", line 1461, in _filter_or_exclude_inplace
    self._query.add_q(Q(*args, **kwargs))
  File "/Users/sunil/miniconda3/envs/django/lib/python3.9/site-packages/django/db/models/sql/query.py", line 1498, in add_q
    clause, _ = self._add_q(q_object, self.used_aliases)
  File "/Users/sunil/miniconda3/envs/django/lib/python3.9/site-packages/django/db/models/sql/query.py", line 1529, in _add_q
    child_clause, needed_inner = self.build_filter(
  File "/Users/sunil/miniconda3/envs/django/lib/python3.9/site-packages/django/db/models/sql/query.py", line 1444, in build_filter
    condition = self.build_lookup(lookups, col, value)
  File "/Users/sunil/miniconda3/envs/django/lib/python3.9/site-packages/django/db/models/sql/query.py", line 1271, in build_lookup
    lookup = lookup_class(lhs, rhs)
  File "/Users/sunil/miniconda3/envs/django/lib/python3.9/site-packages/django/db/models/lookups.py", line 27, in __init__
    self.rhs = self.get_prep_lookup()
  File "/Users/sunil/miniconda3/envs/django/lib/python3.9/site-packages/django/db/models/lookups.py", line 341, in get_prep_lookup
    return super().get_prep_lookup()
  File "/Users/sunil/miniconda3/envs/django/lib/python3.9/site-packages/django/db/models/lookups.py", line 85, in get_prep_lookup
    return self.lhs.output_field.get_prep_value(self.rhs)
  File "/Users/sunil/miniconda3/envs/django/lib/python3.9/site-packages/django/db/models/fields/__init__.py", line 1464, in get_prep_value
    return self.to_python(value)
  File "/Users/sunil/miniconda3/envs/django/lib/python3.9/site-packages/django/db/models/fields/__init__.py", line 1430, in to_python
    raise exceptions.ValidationError(
django.core.exceptions.ValidationError: ['“19850101” value has an invalid date format. It must be in YYYY-MM-DD format.']
20:11:38,801 django.request WARNING Not Found: /api/weather/filter/date=1985-01-01/
20:14:32,60 django.utils.autoreload INFO /Users/sunil/Documents/Corteva/project/weatherData/views.py changed, reloading.
20:14:36,618 django.request WARNING Not Found: /api/weather/filter/date=1985-01-01/
20:16:51,781 django.utils.autoreload INFO /Users/sunil/Documents/Corteva/project/weatherData/serializers.py changed, reloading.
20:16:58,540 django.utils.autoreload INFO /Users/sunil/Documents/Corteva/project/weatherData/serializers.py changed, reloading.
20:17:27,105 django.utils.autoreload INFO /Users/sunil/Documents/Corteva/project/weatherData/serializers.py changed, reloading.
20:17:42,957 django.utils.autoreload INFO /Users/sunil/Documents/Corteva/project/weatherData/views.py changed, reloading.
20:45:52,47 django.utils.autoreload INFO /Users/sunil/Documents/Corteva/project/weatherData/serializers.py changed, reloading.
21:02:24,124 django.utils.autoreload INFO /Users/sunil/Documents/Corteva/project/weatherData/urls.py changed, reloading.
21:04:47,955 django.utils.autoreload INFO /Users/sunil/Documents/Corteva/project/weatherData/serializers.py changed, reloading.
21:04:55,768 django.utils.autoreload INFO /Users/sunil/Documents/Corteva/project/weatherData/views.py changed, reloading.
21:09:49,826 django.utils.autoreload INFO /Users/sunil/Documents/Corteva/project/weatherData/views.py changed, reloading.
21:25:22,454 django.utils.autoreload INFO /Users/sunil/Documents/Corteva/project/project/urls.py changed, reloading.
21:26:09,13 django.utils.autoreload INFO /Users/sunil/Documents/Corteva/project/weatherData/views.py changed, reloading.
